Workbook

Sheet ملخص
A1: مراجعة ملاحظات التعديل غير المحسومة — هيئة الخبراء (جولة 28 سبتمبر 2026)
A2: اقتراح فقط: لا يُطبَّق شيء على حكيم قبل قرار المالك. القرارات المعتمدة تُستورد صفوفًا جديدة في uqn_fix.amendment_review.
A4: الفئة | B4: مؤكد | C4: مرجّح | D4: يحتاج قرار المالك | E4: المجموع | F4: وصف الفئة
A5: الفئة 1 - تعدد | B5: =COUNTIF('الفئة 1 - تعدد'!$K:$K,"مؤكد") -> 90 | C5: =COUNTIF('الفئة 1 - تعدد'!$K:$K,"مرجّح") -> 17 | D5: =COUNTIF('الفئة 1 - تعدد'!$K:$K,"يحتاج قرار المالك") -> 33 | E5: =SUM(B5:D5) -> 140 | F5: أكثر من أداة أو بند في ملاحظة واحدة
A6: الفئة 2 - بلا أداة | B6: =COUNTIF('الفئة 2 - بلا أداة'!$K:$K,"مؤكد") -> 0 | C6: =COUNTIF('الفئة 2 - بلا أداة'!$K:$K,"مرجّح") -> 9 | D6: =COUNTIF('الفئة 2 - بلا أداة'!$K:$K,"يحتاج قرار المالك") -> 61 | E6: =SUM(B6:D6) -> 70 | F6: الأداة غير مقروءة في الملاحظة
A7: الفئة 3 - بلا نص جديد | B7: =COUNTIF('الفئة 3 - بلا نص جديد'!$K:$K,"مؤكد") -> 135 | C7: =COUNTIF('الفئة 3 - بلا نص جديد'!$K:$K,"مرجّح") -> 4 | D7: =COUNTIF('الفئة 3 - بلا نص جديد'!$K:$K,"يحتاج قرار المالك") -> 167 | E7: =SUM(B7:D7) -> 306 | F7: تعديل لا يذكر النص الجديد
A8: الفئة 4 - أثر غير صريح | B8: =COUNTIF('الفئة 4 - أثر غير صريح'!$K:$K,"مؤكد") -> 145 | C8: =COUNTIF('الفئة 4 - أثر غير صريح'!$K:$K,"مرجّح") -> 49 | D8: =COUNTIF('الفئة 4 - أثر غير صريح'!$K:$K,"يحتاج قرار المالك") -> 31 | E8: =SUM(B8:D8) -> 225 | F8: غير مصنف، ملاحظة عامة، جدول، دمج أو ترتيب
A9: المجموع | B9: =SUM(B5:B8) -> 370 | C9: =SUM(C5:C8) -> 79 | D9: =SUM(D5:D8) -> 292 | E9: =SUM(E5:E8) -> 741
A11: عدد الملاحظات المراجَعة | B11: 676 | F11: تتفكك الملاحظة المتعددة الآثار إلى صفوف (معرّف#رقم)
A12: صفوف لها مسودة آلية من صورة الأداة | B12: =COUNTIF('الفئة 1 - تعدد'!$R:$R,"?*")+COUNTIF('الفئة 2 - بلا أداة'!$R:$R,"?*")+COUNTIF('الفئة 3 - بلا نص جديد'!$R:$R,"?*")+COUNTIF('الفئة 4 - أثر غير صريح'!$R:$R,"?*") -> 135 | F12: المسودة للمطابقة بالصورة فقط؛ الأرقام والتواريخ فيها غير موثوقة
A13: قرارات المالك المدخلة | B13: =COUNTA('الفئة 1 - تعدد'!$M:$M)+COUNTA('الفئة 2 - بلا أداة'!$M:$M)+COUNTA('الفئة 3 - بلا نص جديد'!$M:$M)+COUNTA('الفئة 4 - أثر غير صريح'!$M:$M)-4 -> 0
A15: دقة التصنيف الآلي (عينة 20 صفًا مقروءة يدويًا بعد التصحيح) | B15: 19 من 20 | F15: الخطأ الوحيد (ترتيب مع دمج) صُحّحت قاعدته
A17: طريقة الاستعمال
A18: العمودان الأصفران «قرار المالك» و«ملاحظته» لك وحدك. القيم: موافق / مرفوض / موافق مع تصحيح / مؤجل.
A19: «مؤكد»: الأثر صريح والأداة مقروءة والنص الجديد منقول حرفيًا من ملاحظة الهيئة (أو الأثر لا يحتاج نصًا كالحذف والإلغاء).
A20: «مرجّح»: الأثر مستنتج بقاعدة (دمج، ترتيب، إجراء إداري، آثار متعددة) أو الأداة مستنتجة من ملاحظات النظام نفسه.
A21: «يحتاج قرار المالك»: نقص في الدليل، وسببه في عمود «سبب عدم الحسم».
A22: الفئة 3: النص الجديد ليس في الملاحظة؛ افتح «صورة الصفحة» وطابق «المسودة الآلية» بها، ثم اكتب النص الصحيح في «ملاحظته» واختر «موافق مع تصحيح».
A23: صورة الهيئة للمادة تعرض النص الأصلي عند الإصدار؛ النص المعدَّل لا يُؤخذ منها.
A24: مثال: موافق مع تصحيح | «النص الصحيح بعد المطابقة: …».

Sheet الفئة 1 - تعدد
A1: معرّف الملاحظة | B1: النظام | C1: المادة | D1: الفئة | E1: الأثر المقترح | F1: الأداة | G1: تاريخها | H1: النص الجديد (حرفي) | I1: الدليل (اقتباس) | J1: المصدر | K1: الثقة | L1: سبب عدم الحسم | M1: قرار المالك | N1: ملاحظته | O1: رابط مرفق الأداة | P1: صفحة المسودة | Q1: صورة الصفحة | R1: مسودة آلية من الصورة (للمطابقة فقط) | S1: أساس التصنيف | T1: تصنيف المحلل الآلي
A2: boe26-fac1633ef5b79cdca0a0652c#1 | B2: تنظيم المؤسسة العامة للتقاعد | C2: المادة الخامسة : | D2: 1 | E2: إحلال عبارة | H2: أحد عشر عضواً | I2: تم بموجب قرار رقم :(130) وتاريخ: 22/4/1437هـ ، إحلال عبارة " أحد عشر عضواً " محل عبارة "عشرة أعضاء" الواردة في صدر هذه المادة ، و إضافة فقرة جديدة تحمل الرقم ( 9 ) ، وذلك على النحو التالي : 1 - إحلال عبارة "أحد عشر عضواً" محل عبارة "عشرة أعضاء" الواردة في صدر المادة الخامسة من التنظيم . | J2: https://laws.boe.gov.sa/BoeLaws/Laws/LawDetails/5160cfca-da74-4008-97e2-a9a700f23b92/1 | K2: يحتاج قرار المالك | L2: الأداة غير مذكورة في الملاحظة؛ أدوات النظام المرشحة: قرار مجلس الوزراء 461 1436/11/02، قرار مجلس الوزراء 440 1437/10/20، قرار مجلس الوزراء 190 1438/03/20، قرار مجلس الوزراء 429 1440/07/26 | O2: https://laws.boe.gov.sa/BoeLaws/Laws/Viewer/2e8ce9d4-b33b-4f65-8af0-a49b31a65baa?attachmentTitle=المادة الخامسة : | S2: قاعدة: (تعديل|عدل|عدلت)\s+(اسم|مسمي|عباره|العباره)|حل\s+اسم|احلال|ا | T2: add
A3: boe26-fac1633ef5b79cdca0a0652c#2 | B3: تنظيم المؤسسة العامة للتقاعد | C3: المادة الخامسة : | D3: 1 | E3: إضافة فقرة أو مادة | H3: 9 - عضو يرشحه مجلس الشؤون الاقتصادية والتنمية | I3: تم بموجب قرار رقم :(130) وتاريخ: 22/4/1437هـ ، إحلال عبارة " أحد عشر عضواً " محل عبارة "عشرة أعضاء" الواردة في صدر هذه المادة ، و إضافة فقرة جديدة تحمل الرقم ( 9 ) ، وذلك على النحو التالي : 2 - إضافة فقرة جديدة تحمل الرقم ( 9 ) إلى المادة (الخامسة) من التنظيم ، بالنص الاتي : " 9 - عضو يرشحه مجلس الشؤون الاقتصادية والتنمية " . | J3: https://laws.boe.gov.sa/BoeLaws/Laws/LawDetails/5160cfca-da74-4008-97e2-a9a700f23b92/1 | K3: يحتاج قرار المالك | L3: الأداة غير مذكورة في الملاحظة؛ أدوات النظام المرشحة: قرار مجلس الوزراء 461 1436/11/02، قرار مجلس الوزراء 440 1437/10/20، قرار مجلس الوزراء 190 1438/03/20، قرار مجلس الوزراء 429 1440/07/26 | O3: https://laws.boe.gov.sa/BoeLaws/Laws/Viewer/2e8ce9d4-b33b-4f65-8af0-a49b31a65baa?attachmentTitle=المادة الخامسة : | S3: قاعدة: (^|\s|-)(يضاف|تضاف|اضافه|اضيفت|اضيف)\s | T3: add
A4: boe26-a19bc93f371031ebc7f36a58#2 | B4: تنظيم الهيئة السعودية للمواصفات والمقاييس والجودة | C4: المادة الثامنة : | D4: 1 | E4: إضافة فقرة أو مادة | F4: قرار مجلس الوزراء رقم (693) | G4: 1441/11/02 | I4: - إضافة ممثل لوزارة الصناعة والثروة المعدنية إلى عضوية مجلس إدارة الهيئة ، وذلك بموجب قرار مجلس الوزراء رقم (693) وتاريخ 1441/11/2هـ. | J4: https://laws.boe.gov.sa/BoeLaws/Laws/LawDetails/2734fa93-a1a6-4c38-8e0d-a9a700f1e46f/1 | K4: يحتاج قرار المالك | L4: النص الجديد غير مذكور في الملاحظة؛ عنوان المادة في صورة المرفق (ص 4، السياق: أداة تعديل)، والمقتطف الآلي مسودة تُطابق بالصورة ثم يُنقل النص حرفيًا | O4: https://laws.boe.gov.sa/BoeLaws/Laws/Viewer/75452b4e-9ee9-4dc8-a786-a9a700f1e4e4 | P4: 4 | Q4: https://laws.boe.gov.sa/BoeLaws/Laws/GetViewerImage/?imageFileName=980abbb6-b359-4b87-b2d5-abef00a1d265_Page_004.jpg | R4: ثالثا:تعديل صدر الفقرة (”) من المادة (الثامنة عشرة) من اللائحة التنفيذية النظام مكافحة المخدرات والمؤثرات العقلية الصادرة بقرار مجلس الوزراء رقم (١١؟‏ وتاريخ ‎41/1/٠١‏ ١هء‏ ليكون بالنص الآتي: "تشكل في الهيئة العامة للغذاء والدواء لجنة دائمة من كل من وزارة الداخلية» ووزارة الصناعة والشروة المعدنية» ووزارة الصحة» تتولى مباشرة المهمات الآتية:...". رابعاً :تعديل تنظيم المركز السعودي لكفاءة الطاقة» الصادر بقرار مجلس الوزداء رقم (0) وتاريخ 4174/1/7 ١هء‏ وذلك على النحو الآتي: ‎-١‏ إحلال عبارة (وزارة الطاقة) محل عبارة (وزارة الطاقة والصناعة والشروة المعدنية)؛ وعبارة (وزير الطاقة) محل عبارة (وزير الطاقة والصناعة والشروة المعدنية)» أينما وردتا في التنظيم. 7- إضافة ممثل من وزارة الصناعة والشروة المعدنية إلى عضوية مجلس إدارة المركز المنصوص على تشكيله في المادة (الخامسة) من التنظيم. خامساً:تعديل تنظيم المركز الوطني للتنافسية» الصادر بقرار مجلس الوزداء رقم (15؟) وتاريخ 4/70 /* 4 4 ١ه»ء‏ وذلك على النحو | S4: قاعدة: (^|\s|-)(يضاف|تضاف|اضافه|اضيفت|اضيف)\s | T4: add
A5: boe26-13dcdb490564a31d4687b6dd#1 | B5: تنظيم الهيئة العامة للإحصاء | C5: المادة السابعة: | D5: 1 | E5: نص مادة معروض بلا صيغة تعديل | I5: • المادة السابعة | J5: https://laws.boe.gov.sa/BoeLaws/Laws/LawDetails/a7119cfe-7668-488f-853f-a9a700f1ea6c/1 | K5: يحتاج قرار المالك | L5: الملاحظة نص مادة بلا أداة ولا فعل تعديل | O5: https://laws.boe.gov.sa/BoeLaws/Laws/Viewer/c95ec6fc-7ed8-4935-a809-abff00dcc27a?attachmentTitle= المادة السابعة: | S5: لا فعل تعديل في الملاحظة | T5: amend_article
A6: boe26-13dcdb490564a31d4687b6dd#2 | B6: تنظيم الهيئة العامة للإحصاء | C6: المادة السابعة: | D6: 1 | E6: تعديل مادة | F6: قرار مجلس الوزراء رقم (212) | G6: 1441/03/15 | I6: - عُدلت هذه المادة من التنظيم بموجب قرار مجلس الوزراء رقم (212) وتاريخ 15 / 3 / 1441هـ | J6: https://laws.boe.gov.sa/BoeLaws/Laws/LawDetails/a7119cfe-7668-488f-853f-a9a700f1ea6c/1 | K6: يحتاج قرار المالك | L6: النص الجديد غير مذكور في الملاحظة؛ عنوان المادة في صورة المرفق (ص 1، السياق: أداة تعديل)، والمقتطف الآلي مسودة تُطابق بالصورة ثم يُنقل النص حرفيًا | O6: https://laws.boe.gov.sa/BoeLaws/Laws/Viewer/c95ec6fc-7ed8-4935-a809-abff00dcc27a?attachmentTitle= المادة السابعة: | P6: 1 | Q6: https://laws.boe.gov.sa/BoeLaws/Laws/GetViewerImage/?imageFileName=c95ec6fc-7ed8-4935-a809-abff00dcc27a_Page_001.jpg | R6: ا الموافقة على تعديل المادة (السابعة) من تنظيم الهيئة العامة للإحصاء لتصبح بالنص الآتيه "٠-يشكل‏ المجلس على النحو الآتي: ا أ - وزير الاقتصاد والتخطيط. رفيساً ‏ | ب - وزير الطاقة. عضواً اج - وذير التجارة. عضواً د - وزير المالية. عضواً | ) 0 ه- وزير الموارد البشرية والتنمية الاجتماعية. عضواً / و - وذير التعليم. عضواً أ | S6: قاعدة: (عدلت|عدل|تعديل|تعديلات|يعدل|ليعدل)\b.{0,40}(الماده|المواد)| | T6: amend_article
A7: boe26-41935b1b6795a7539ced821c#1 | B7: تنظيم الهيئة العامة للإحصاء | C7: المادة العاشرة: | D7: 1 | E7: نص مادة معروض بلا صيغة تعديل | I7: • المادة العاشرة | J7: https://laws.boe.gov.sa/BoeLaws/Laws/LawDetails/a7119cfe-7668-488f-853f-a9a700f1ea6c/1 | K7: يحتاج قرار المالك | L7: الملاحظة نص مادة بلا أداة ولا فعل تعديل | O7: https://laws.boe.gov.sa/BoeLaws/Laws/Viewer/dba9feac-6408-4e0e-bd14-ab0c00b9aedb?attachmentTitle= المادة العاشرة: | S7: لا فعل تعديل في الملاحظة | T7: amend_article
A8: boe26-41935b1b6795a7539ced821c#2 | B8: تنظيم الهيئة العامة للإحصاء | C8: المادة العاشرة: | D8: 1 | E8: إحلال عبارة | H8: يكون للهيئة رئيس يُعين ويعفى من منصبه بقرار من المجلس، ويحدد القرار أجره ومزاياه المالية الأخرى | I8: - عُدل صدر هذه المادة، وذلك بإحلال عبارة "يكون للهيئة رئيس يُعين ويعفى من منصبه بقرار من المجلس، ويحدد القرار أجره ومزاياه المالية الأخرى" محل عبارة "يكون للهيئة رئيس بالمرتبة الممتازة". | J8: https://laws.boe.gov.sa/BoeLaws/Laws/LawDetails/a7119cfe-7668-488f-853f-a9a700f1ea6c/1 | K8: يحتاج قرار المالك | L8: الأداة غير مذكورة في الملاحظة؛ أدوات النظام المرشحة: قرار مجلس الوزراء 212 1441/03/15، قرار مجلس الوزراء 745 1441/11/23، قرار مجلس الوزراء 198 1442/03/24 | O8: https://laws.boe.gov.sa/BoeLaws/Laws/Viewer/dba9feac-6408-4e0e-bd14-ab0c00b9aedb?attachmentTitle= المادة العاشرة: | S8: قاعدة: (تعديل|عدل|عدلت)\s+(اسم|مسمي|عباره|العباره)|حل\s+اسم|احلال|ا | T8: amend_article
A9: boe26-972993bcc63a0b311d261d4e#2 | B9: تنظيم الهيئة العامة للعقار | C9: المادة الرابعة: | D9: 1 | E9: إضافة فقرة أو مادة | F9: قرار مجلس الوزراء رقم (693) | G9: 1441/11/02 | I9: - إضافة ممثل عن وزارة الصناعة والثروة المعدنية إلى عضوية مجلس إدارة الهيئة، المنصوص على تشكيله في الفقرة (1) من هذه المادة وذلك بموجب قرار مجلس الوزراء رقم (693) وتاريخ 1441/11/2هـ. | J9: https://laws.boe.gov.sa/BoeLaws/Laws/LawDetails/a98158eb-927b-4f8c-a9ff-a9a700f21e78/1 | K9: يحتاج قرار المالك | L9: النص الجديد غير مذكور في الملاحظة؛ عنوان المادة في صورة المرفق (ص 2، السياق: أداة تعديل)، والمقتطف الآلي مسودة تُطابق بالصورة ثم يُنقل النص حرفيًا | O9: https://laws.boe.gov.sa/BoeLaws/Laws/Viewer/206d5898-51b8-4a42-ad0b-b36300ca8877?attachmentTitle=المادة الرابعة: | P9: 2 | Q9: https://laws.boe.gov.sa/BoeLaws/Laws/GetViewerImage/?imageFileName=206d5898-51b8-4a42-ad0b-b36300ca8877_Page_002.jpg | R9: ثالثا : تعديل الفقرة ‎)١(‏ من المادة (الرابعة) من تنظيم الهيئة العامة للعقار؛ الصادر بقسراد مجلس الوزراء رقم (575) وتاريخ 4154/4/78 ١هىء‏ لتكون بالنص الآتي: "يكون للهيئة مجلس إدارة برئاسة الوذيرء وعضوية كل من: : 1 - الرئيس:التتفيذي. ب- ممثل هن وزارة الداخلية. ج - ممثل من وزارة البلديات والإسكان. ا د - ممثل من وذارة المالية. ه- ممثل. من وزارة العدل. 1 و - ممثل من وذارة الاقتصاد والتخطيط. ز - ممثل من وزارة الاستثمار. ح - ممثل-من وزارة البيئة والمياه والزراعة. ط - ممثل من وزارة الصناعة والثروة المعدنية. ي - ممثل من الهيتة العامة لعقارات الدولة. ك-' ممثل من الهيثة العامة للمساحة والمعلومات الجيومكانية. ْ | S9: قاعدة: (^|\s|-)(يضاف|تضاف|اضافه|اضيفت|اضيف)\s | T9: add
A10: boe26-512a270796442773c79a93d7#1 | B10: تنظيم صندوق الشهداء والمصابين والأسرى والمفقودين | C10: المادة الأولى : التعريفات : | D10: 1 | E10: نص مادة معروض بلا صيغة تعديل | I10: • تعريف الوزير في المادة الأولى | J10: https://laws.boe.gov.sa/BoeLaws/Laws/LawDetails/62d14b10-5bee-46e9-870a-a9a700f19762/1 | K10: يحتاج قرار المالك | L10: الملاحظة نص مادة بلا أداة ولا فعل تعديل | O10: https://laws.boe.gov.sa/BoeLaws/Laws/Viewer/66de474c-549c-4b8c-9116-aa1c01702900?attachmentTitle=المادة الأولى : التعريفات : | S10: لا فعل تعديل في الملاحظة | T10: delete
A11: boe26-512a270796442773c79a93d7#2 | B11: تنظيم صندوق الشهداء والمصابين والأسرى والمفقودين | C11: المادة الأولى : التعريفات : | D11: 1 | E11: غير مصنف | F11: قرار مجلس الوزراء رقم (707) | G11: 1440/12/26 | I11: - حذف هذا التعريف بموجب قرار مجلس الوزراء رقم (707) وتاريخ 26/ 12/ 1440هـ. | J11: https://laws.boe.gov.sa/BoeLaws/Laws/LawDetails/62d14b10-5bee-46e9-870a-a9a700f19762/1 | K11: يحتاج قرار المالك | L11: الأثر غير صريح في الملاحظة | O11: https://laws.boe.gov.sa/BoeLaws/Laws/Viewer/66de474c-549c-4b8c-9116-aa1c01702900?attachmentTitle=المادة الأولى : التعريفات : | S11: لا قاعدة | T11: delete
A12: boe26-2df09f2a8b50256dc4c5f51b#3 | B12: تنظيم هيئات تطوير المناطق والمدن واللائحة المالية لهيئات تطوير المناطق والمدن واللائحة الإدارية لهيئات تطوير المناطق والمدن | C12: المادة الخامسة | D12: 1 | E12: إضافة فقرة أو مادة | F12: قرار مجلس الوزراء رقم (375) | G12: 1443/07/07 | I12: * عُدلت هذه المادة وذلك بموجب قرار مجلس الوزراء رقم (375) وتاريخ 1443/7/7هـ، وذلك على النحو الآتي: - إضافة عبارتين إلى الفقرة (1)، بالنصين الآتيين: "- ممثل من وزارة الطاقة عضواً". "- ممثل من وزارة الصناعة والثروة المعدنية عضواً". | J12: https://laws.boe.gov.sa/BoeLaws/Laws/LawDetails/2ae2b616-e5c9-4b81-b55e-ae3d00acbf1a/1 | K12: يحتاج قرار المالك | L12: النص الجديد غير مذكور في الملاحظة؛ عنوان المادة في صورة المرفق (ص 1، السياق: أداة تعديل)، والمقتطف الآلي مسودة تُطابق بالصورة ثم يُنقل النص حرفيًا | O12: https://laws.boe.gov.sa/BoeLaws/Laws/Viewer/69c457f0-9841-49aa-b6c1-ae6d00f4d507?attachmentTitle=المادة الخامسة | P12: 1 | Q12: https://laws.boe.gov.sa/BoeLaws/Laws/GetViewerImage/?imageFileName=69c457f0-9841-49aa-b6c1-ae6d00f4d507_Page_001.jpg | R12: ‏أولاً : تعديل المادة (الخامسة) من تنظيم هيئات تطوير المناطق والمدنء الصادر بقرار ‏مجلس الوزراء رقم (47) وتاريخ 44/4/17 ١هء‏ وذلك على النحو الآتي: ‎| .)١( ‏حذف عبارة "- ممثل من الشركة السعودية للكهرباء عضو" الواردة في الفقرة‎ -١ ‏7 - حذف عبارة "» وممثل من شركة أرامكو السعوديةء" الواردة في الفقرة (4). | S12: قاعدة: (^|\s|-)(يضاف|تضاف|اضافه|اضيفت|اضيف)\s | T12: delete
A13: boe26-d9e71ba415078dbf3fe5bf4a#2 | B13: تنظيم هيئة تنظيم المياه والكهرباء ( الهيئة السعودية لتنظيم الكهرباء ) | C13: المادة الأولى | D13: 1 | E13: غير مصنف | F13: قرار مجلس الوزراء رقم (918) | G13: 1445/10/28 | I13: - حذف تعريف "نشاط المياه"، وذلك بموجب قرار مجلس الوزراء رقم (918) وتاريخ 1445/10/28هـ. | J13: https://laws.boe.gov.sa/BoeLaws/Laws/LawDetails/36ccdf4a-396d-48aa-8231-acb0009c3cbd/1 | K13: يحتاج قرار المالك | L13: الأثر غير صريح في الملاحظة | O13: https://laws.boe.gov.sa/BoeLaws/Laws/Viewer/cc637e06-fc9e-484e-80cf-b1760090ea8a?attachmentTitle=المادة الأولى | S13: لا قاعدة | T13: delete
A14: boe26-f6202174dcc920e4d990f9d1#1 | B14: نظام الأوسمة السعودية | C14: المادة التاسعة: | D14: 1 | E14: إضافة فقرة أو مادة | H14: ووسام الملك سلمان | I14: تعديل المادة (التاسعة) وذلك على النحو الآتي: أ- إضافة عبارة "ووسام الملك سلمان" بعد عبارة "ووسام الملك عبدالله"، الواردة في ديباجة المادة. | J14: https://laws.boe.gov.sa/BoeLaws/Laws/LawDetails/9ba0d5dc-2dc4-4b71-b979-a9a700f1f5fd/1 | K14: يحتاج قرار المالك | L14: الأداة غير مذكورة في الملاحظة، ولا أداة في ملاحظات النظام | O14: https://laws.boe.gov.sa/BoeLaws/Laws/Viewer/777a95f3-0f71-4bb7-8b3e-aa1c01353cfb?attachmentTitle=المادة التاسعة : | S14: قاعدة: (^|\s|-)(يضاف|تضاف|اضافه|اضيفت|اضيف)\s | T14: amend_article
A15: boe26-f6202174dcc920e4d990f9d1#2 | B15: نظام الأوسمة السعودية | C15: المادة التاسعة: | D15: 1 | E15: إضافة فقرة أو مادة | H15: 6- يمنح وسام الملك سلمان تقديراً للمتميزين في مجالات التاريخ الوطني والعربي والإسلامي، والمكتبات، وخدمة المخطوطات والوثائق التاريخية، والإعلام والثقافة، وتنمية السياحة الوطنية، ولأصحاب المبادرات البارزة في الأعمال الخيرية والإغاثية | I15: تعديل المادة (التاسعة) وذلك على النحو الآتي: ب- إضافة فقرة إلى نهاية المادة لتكون بالنص الآتي: "6- يمنح وسام الملك سلمان تقديراً للمتميزين في مجالات التاريخ الوطني والعربي والإسلامي، والمكتبات، وخدمة المخطوطات والوثائق التاريخية، والإعلام والثقافة، وتنمية السياحة الوطنية، ولأصحاب المبادرات البارزة في الأعمال الخيرية والإغاثية". | J15: https://laws.boe.gov.sa/BoeLaws/Laws/LawDetails/9ba0d5dc-2dc4-4b71-b979-a9a700f1f5fd/1 | K15: يحتاج قرار المالك | L15: الأداة غير مذكورة في الملاحظة، ولا أداة في ملاحظات النظام | O15: https://laws.boe.gov.sa/BoeLaws/Laws/Viewer/777a95f3-0f71-4bb7-8b3e-aa1c01353cfb?attachmentTitle=المادة التاسعة : | S15: قاعدة: (^|\s|-)(يضاف|تضاف|اضافه|اضيفت|اضيف)\s | T15: amend_article
A16: boe26-fc92d186b5c514d15b5f3a24#1 | B16: نظام البريد | C16: المادة الأولى | D16: 1 | E16: غير مصنف | F16: قرار مجلس الوزراء رقم (705) | G16: 1443/12/27 | I16: * صدر قرار مجلس الوزراء رقم (705) وتاريخ 1443/12/27هـ. المتضمن في الفقرة (رابعاً) الآتي: - حذف تعريف (الوزارة). | J16: https://laws.boe.gov.sa/BoeLaws/Laws/LawDetails/8ca91427-5be7-4807-80ae-adc700a97f0d/1 | K16: يحتاج قرار المالك | L16: الأثر غير صريح في الملاحظة | O16: https://laws.boe.gov.sa/BoeLaws/Laws/Viewer/90fef0b3-713c-45f2-9a80-aef500eb0817?attachmentTitle=المادة الأولى | S16: لا قاعدة | T16: delete
A17: boe26-79374d449c77f7d6afec6ade#1 | B17: نظام البنك السعودي للتسليف والادخار ( بنك التنمية الاجتماعية ) | C17: المادة الأولى: | D17: 1 | E17: نص مادة معروض بلا صيغة تعديل | I17: • المادة الأولى | J17: https://laws.boe.gov.sa/BoeLaws/Laws/LawDetails/90b81287-baab-4f66-a9c1-a9a700f2ce78/1 | K17: يحتاج قرار المالك | L17: الملاحظة نص مادة بلا أداة ولا فعل تعديل | O17: https://laws.boe.gov.sa/BoeLaws/Laws/Viewer/37089388-c254-4d9d-88c6-dc0f29b469ff?attachmentTitle=المادة الأولى: | S17: لا فعل تعديل في الملاحظة | T17: substitute_phrase
A18: boe26-330c796e951a350c6911129f#2 | B18: نظام البنك السعودي للتسليف والادخار ( بنك التنمية الاجتماعية ) | C18: المادة الرابعة: | D18: 1 | E18: إضافة فقرة أو مادة | F18: قرار مجلس الوزراء رقم (75) | G18: 1438/01/30 | I18: تم تعديل الفقرة (د) من هذه المادة و إضافة فقرة جديدة تحمل ( هـ ) ، بموجب قرار مجلس الوزراء رقم: (75) وتاريخ: 30/ 1/ 1438هـ ، كما يلى : 2 – إضافة فقرة جديدة تنص على ما يلي: "هـ – تقديم قروض دون فائدة وخدمات غير مالية للجمعيات والمؤسسات الأهلية بما يمكنها من المساهمة في تقديم الخدمات للشرائح التي يستهدفها البنك". | J18: https://laws.boe.gov.sa/BoeLaws/Laws/LawDetails/90b81287-baab-4f66-a9c1-a9a700f2ce78/1 | K18: يحتاج قرار المالك | L18: النص الجديد غير مذكور في الملاحظة؛ عنوان المادة في صورة المرفق (ص 2، السياق: أداة تعديل)، والمقتطف الآلي مسودة تُطابق بالصورة ثم يُنقل النص حرفيًا | O18: https://laws.boe.gov.sa/BoeLaws/Laws/Viewer/a0046fbe-715d-4017-96f6-ab0c00c59d21?attachmentTitle=المادة الرابعة: | P18: 2 | Q18: https://laws.boe.gov.sa/BoeLaws/Laws/GetViewerImage/?imageFileName=a0046fbe-715d-4017-96f6-ab0c00c59d21_Page_002.jpg | R18: ‎-١‏ إضافة الفقرات (وء ز» ح) إلى المادة (الرابعة)» تكون بالنص الآتي: "و- تقديم قروض دون فائدة للمنشآت الصغيرة والناشئة بما يساعد في رفع مساهمتها في الاقتصاد الوطني وإيجاد فرص للعمل. ز- تقديم خدمات فنية وإدارية مساندة للمنشآت المستفيدة من خدمات البنك الرفع كفايتها وزيادة فرص نجاحها. ا ح- تحفيز القطاع الخاص للمشاركة في المسؤولية الاجتماعية بإدارة المحافظ المالية الخاصة من قبل البنك وتوجيهها للمستفيدين من خدماته بما بيحقق غايات الإنماء الاجتماعي". 7- حذف عبارة "واللوائح المالية» والإدارية" الواردة في عجز الفقرة (أ) من المادة (التاسسعة). '- إضافة الفقرة (م) إلى المادة (التاسعة) تكون بالنص الآتي: "م- إقرار اللوائح الإدارية والمالية التي يسير عليها البنك وغيرها من اللوائح والإجراءات الداخلية والفنية اللازمة لتسيير شؤون البنك. على أن يكون إقرار اللوائح المالية والاحكام ذات الأثر المالي في اللوائح الإدارية بالاتفاق مع وزارة المالية". 4- إحلال كلمة "نائب" محل كلمة "مساعد" الواردة في صدر ا | S18: قاعدة: (^|\s|-)(يضاف|تضاف|اضافه|اضيفت|اضيف)\s | T18: amend_paragraph
A19: boe26-904c9fc76f219f78016962ce#2 | B19: نظام التأمينات الاجتماعية 1421هـ | C19: المادة العاشرة : | D19: 1 | E19: إضافة فقرة أو مادة | F19: قرار مجلس الوزراء رقم (190) | G19: 1438/03/20 | I19: تم تعديل هذه المادة بموجب قرار مجلس الوزراء رقم (190) وتاريخ 20/ 3/ 1438هـ ، وذلك على النحو الآتي: ب – إضافة محافظ المؤسسة العامة للتقاعد إلى تشكيل المجلس الوارد في الفقرة رقم (1). | J19: https://laws.boe.gov.sa/BoeLaws/Laws/LawDetails/8ff3cd90-e466-4bf9-a071-a9a700f2a70d/1 | K19: يحتاج قرار المالك | L19: النص الجديد غير مذكور في الملاحظة؛ عنوان المادة في صورة المرفق (ص 2، السياق: نص نظام أو سياق غير صريح)، والمقتطف الآلي مسودة تُطابق بالصورة ثم يُنقل النص حرفيًا | O19: https://laws.boe.gov.sa/BoeLaws/Laws/Viewer/5988d323-2503-4231-a4eb-acf200a6cbec?attachmentTitle=المادة العاشرة : | P19: 2 | Q19: https://laws.boe.gov.sa/BoeLaws/Laws/GetViewerImage/?imageFileName=5988d323-2503-4231-a4eb-acf200a6cbec_Page_002.jpg | R19: من المادة (العاشرة). ثانيا: تعديل نظام تبادل المنافع بين نظامي التقاعد المدني والعسكري ونظام التأمينات الاجتماعية - الصادر بالمرسوم الملكي رقم (م/07) وتاريخ 4174/19/77 اه على النحو الآتي: ‎-١‏ تعديل الفقرة 77) من المادة (السادسة) وذلك بإحلال عبارة (وزير المالية) محل كلمة (الوزير)» وحذف عبارة (المشرف على الجهة) الواردة بعد عبارة (يختارهم الوزير)؛ وحذف عبارة (ويتفق الوزيران على من يتولى رئاسة اللجنة في دورتها الأولى) الواردة بعد عبارة (وعند التساوي يرجح الجانب الذي منه رئيس اللجنة)؛ لتكون الفقسرة بعد التعديل بالنص التالي: "تكوين لجنة من كل من المؤسسة العامة للتأمينات الاجتماعية؛ والمؤسسة العامة للتقاعد, يمثل كل جهة ثلاثة أعضاء يختارهم وزير المالية» على أن يكونوا من أعضاء مجلس الإدارة أو من كبار العاملين بهاء وتكون مهمة ‏1 اللجنة مباشرة الاختصاصات الآتية: | S19: قاعدة: (^|\s|-)(يضاف|تضاف|اضافه|اضيفت|اضيف)\s | T19: amend_article
A20: boe26-904c9fc76f219f78016962ce#3 | B20: نظام التأمينات الاجتماعية 1421هـ | C20: المادة العاشرة : | D20: 1 | E20: إضافة فقرة أو مادة | F20: قرار مجلس الوزراء رقم (190) | G20: 1438/03/20 | I20: تم تعديل هذه المادة بموجب قرار مجلس الوزراء رقم (190) وتاريخ 20/ 3/ 1438هـ ، وذلك على النحو الآتي: ج – إضافة عضو يرشحه مجلس الشؤون الاقتصادية والتنمية إلى تشكيل المجلس الوارد في الفقرة رقم (1). | J20: https://laws.boe.gov.sa/BoeLaws/Laws/LawDetails/8ff3cd90-e466-4bf9-a071-a9a700f2a70d/1 | K20: يحتاج قرار المالك | L20: النص الجديد غير مذكور في الملاحظة؛ عنوان المادة في صورة المرفق (ص 2، السياق: نص نظام أو سياق غير صريح)، والمقتطف الآلي مسودة تُطابق بالصورة ثم يُنقل النص حرفيًا | O20: https://laws.boe.gov.sa/BoeLaws/Laws/Viewer/5988d323-2503-4231-a4eb-acf200a6cbec?attachmentTitle=المادة العاشرة : | P20: 2 | Q20: https://laws.boe.gov.sa/BoeLaws/Laws/GetViewerImage/?imageFileName=5988d323-2503-4231-a4eb-acf200a6cbec_Page_002.jpg | R20: من المادة (العاشرة). ثانيا: تعديل نظام تبادل المنافع بين نظامي التقاعد المدني والعسكري ونظام التأمينات الاجتماعية - الصادر بالمرسوم الملكي رقم (م/07) وتاريخ 4174/19/77 اه على النحو الآتي: ‎-١‏ تعديل الفقرة 77) من المادة (السادسة) وذلك بإحلال عبارة (وزير المالية) محل كلمة (الوزير)» وحذف عبارة (المشرف على الجهة) الواردة بعد عبارة (يختارهم الوزير)؛ وحذف عبارة (ويتفق الوزيران على من يتولى رئاسة اللجنة في دورتها الأولى) الواردة بعد عبارة (وعند التساوي يرجح الجانب الذي منه رئيس اللجنة)؛ لتكون الفقسرة بعد التعديل بالنص التالي: "تكوين لجنة من كل من المؤسسة العامة للتأمينات الاجتماعية؛ والمؤسسة العامة للتقاعد, يمثل كل جهة ثلاثة أعضاء يختارهم وزير المالية» على أن يكونوا من أعضاء مجلس الإدارة أو من كبار العاملين بهاء وتكون مهمة ‏1 اللجنة مباشرة الاختصاصات الآتية: | S20: قاعدة: (^|\s|-)(يضاف|تضاف|اضافه|اضيفت|اضيف)\s | T20: amend_article
A21: boe26-fbd186321093f8393d5c0741 | B21: نظام التقاعد العسكري | C21: المادة (4): | D21: 1 | E21: قرار صادر بشأن المادة | F21: قرار مجلس الوزراء رقم (1212) | G21: 1397/09/23 | I21: صدر بشأن هذه الفقرة قراري مجلس الوزراء رقم (1212) وتاريخ 23 / 9 / 1397 هـ ورقم (247) وتاريخ 21 / 2 / 1398 هـ ، كما صدر بشأنها مرسوم ملكي رقم (م/48) وتاريخ 12 / 8 / 1403 هـ . | J21: https://laws.boe.gov.sa/BoeLaws/Laws/LawDetails/0838afd4-ca76-4b4a-b1d1-a9a700f22afd/1 | K21: يحتاج قرار المالك | L21: الملاحظة تذكر قرارًا صادرًا بشأن المادة ولا تذكر أثره | O21: https://laws.boe.gov.sa/BoeLaws/Laws/Viewer/a1254ed8-6853-49be-b0fb-b856424834c5?attachmentTitle=المادة (4): | S21: قاعدة: «صدر بشأن» | T21: general
A22: boe26-f3391296374cda39c289cf15#1 | B22: نظام الصندوق السعودي للتنمية | C22: المادة الرابعة: | D22: 1 | E22: نص مادة معروض بلا صيغة تعديل | I22: • المادة الرابعة | J22: https://laws.boe.gov.sa/BoeLaws/Laws/LawDetails/7017dc70-15bb-4137-b87d-a9a700f1b950/1 | K22: يحتاج قرار المالك | L22: الملاحظة نص مادة بلا أداة ولا فعل تعديل | O22: https://laws.boe.gov.sa/BoeLaws/Laws/Viewer/24051991-772a-46db-99b2-2773eeae6df9?attachmentTitle=المادة الرابعة: | S22: لا فعل تعديل في الملاحظة | T22: amend_article
A23: boe26-f3391296374cda39c289cf15#2 | B23: نظام الصندوق السعودي للتنمية | C23: المادة الرابعة: | D23: 1 | E23: تعديل مادة | F23: قرار مجلس الوزراء رقم (182) | G23: 1441/03/01 | I23: - عٌدلت هذه المادة بموجب قرار مجلس الوزراء رقم (182) وتاريخ 1 / 3 / 1441هـ. | J23: https://laws.boe.gov.sa/BoeLaws/Laws/LawDetails/7017dc70-15bb-4137-b87d-a9a700f1b950/1 | K23: يحتاج قرار المالك | L23: النص الجديد غير مذكور في الملاحظة؛ عنوان المادة في صورة المرفق (ص 1، السياق: أداة تعديل)، والمقتطف الآلي مسودة تُطابق بالصورة ثم يُنقل النص حرفيًا | O23: https://laws.boe.gov.sa/BoeLaws/Laws/Viewer/24051991-772a-46db-99b2-2773eeae6df9?attachmentTitle=المادة الرابعة: | P23: 1 | Q23: https://laws.boe.gov.sa/BoeLaws/Laws/GetViewerImage/?imageFileName=24051991-772a-46db-99b2-2773eeae6df9_Page_001.jpg | R23: ثانيأ : إضافة فقرة جديدة برقم ‎)١(‏ مكرر إلى المادة (الرابعة) من النظام بالنص الآتي: "إقرار قواعد وشروط تقديم منح المعونة الفنية لتمويل الدراسات والدعم المؤسسي» على ألا يتجاوز المبلغ الإجمالي السنوي لها ما نسبته اثنان في الماثة (7:) من صاني دخل الصندوق". | S23: قاعدة: (عدلت|عدل|تعديل|تعديلات|يعدل|ليعدل)\b.{0,40}(الماده|المواد)| | T23: amend_article
A24: boe26-8acdcdde10da081718d0b87e#3 | B24: نظام المقيمين المعتمدين | C24: المادة الأولى: تعريفات : | D24: 1 | E24: إضافة فقرة أو مادة | F24: مرسوم ملكي رقم (م/190) | G24: 1444/11/22 | I24: - عُدلت هذه المادة وذلك بموجب المرسوم الملكي رقم (م/190) وتاريخ 1444/11/22هـ، وذلك على النحو الآتي: 3- إضافة تعريف "المجلس: مجلس إدارة الهيئة". | J24: https://laws.boe.gov.sa/BoeLaws/Laws/LawDetails/cad66e4d-38d3-4baa-8049-a9a700f1e7a8/1 | K24: يحتاج قرار المالك | L24: النص الجديد غير مذكور؛ للمادة مرفق أداة يلزم قراءته | O24: https://laws.boe.gov.sa/BoeLaws/Laws/Viewer/02079452-a370-450c-87a7-ac3700b202a3?attachmentTitle=المادة الأولى: تعريفات : | S24: قاعدة: (^|\s|-)(يضاف|تضاف|اضافه|اضيفت|اضيف)\s | T24: amend_definition
A25: boe26-cb2270e18fc5400cca62e87f#1 | B25: نظام المقيمين المعتمدين | C25: المادة الخامسة والثلاثون : | D25: 1 | E25: قرار صادر بشأن المادة | F25: مرسوم ملكي رقم (م/190) | G25: 1444/11/22 | I25: - صدر المرسوم الملكي رقم (م/190) وتاريخ 1444/11/22هـ، ونص على الآتي: | J25: https://laws.boe.gov.sa/BoeLaws/Laws/LawDetails/cad66e4d-38d3-4baa-8049-a9a700f1e7a8/1 | K25: يحتاج قرار المالك | L25: الملاحظة تذكر قرارًا صادرًا بشأن المادة ولا تذكر أثره | O25: https://laws.boe.gov.sa/BoeLaws/Laws/Viewer/ea6a7b0c-de4b-4b29-b7b2-b02600af0044?attachmentTitle=المادة الخامسة والثلاثون : | S25: قاعدة: «صدر بشأن» | T25: add
A26: boe26-cb2270e18fc5400cca62e87f#2 | B26: نظام المقيمين المعتمدين | C26: المادة الخامسة والثلاثون : | D26: 1 | E26: إحلال عبارة | H26: الهيئة | I26: - إحلال كلمة "الهيئة" محل عبارة "الجهة المشرفة". | J26: https://laws.boe.gov.sa/BoeLaws/Laws/LawDetails/cad66e4d-38d3-4baa-8049-a9a700f1e7a8/1 | K26: يحتاج قرار المالك | L26: الأداة غير مذكورة في الملاحظة؛ أدوات النظام المرشحة: مرسوم ملكي م/109 1441/08/22، قرار مجلس الوزراء 57 1442/01/20، قرار مجلس الوزراء 123 1443/02/21، مرسوم ملكي م/190 1444/11/22 | O26: https://laws.boe.gov.sa/BoeLaws/Laws/Viewer/ea6a7b0c-de4b-4b29-b7b2-b02600af0044?attachmentTitle=المادة الخامسة والثلاثون : | S26: قاعدة: (تعديل|عدل|عدلت)\s+(اسم|مسمي|عباره|العباره)|حل\s+اسم|احلال|ا | T26: add
A27: boe26-cb2270e18fc5400cca62e87f#3 | B27: نظام المقيمين المعتمدين | C27: المادة الخامسة والثلاثون : | D27: 1 | E27: إحلال عبارة | H27: المجلس | I27: - إحلال "المجلس" محل "الرئيس". | J27: https://laws.boe.gov.sa/BoeLaws/Laws/LawDetails/cad66e4d-38d3-4baa-8049-a9a700f1e7a8/1 | K27: يحتاج قرار المالك | L27: الأداة غير مذكورة في الملاحظة؛ أدوات النظام المرشحة: مرسوم ملكي م/109 1441/08/22، قرار مجلس الوزراء 57 1442/01/20، قرار مجلس الوزراء 123 1443/02/21، مرسوم ملكي م/190 1444/11/22 | O27: https://laws.boe.gov.sa/BoeLaws/Laws/Viewer/ea6a7b0c-de4b-4b29-b7b2-b02600af0044?attachmentTitle=المادة الخامسة والثلاثون : | S27: قاعدة: (تعديل|عدل|عدلت)\s+(اسم|مسمي|عباره|العباره)|حل\s+اسم|احلال|ا | T27: add
A28: boe26-cb2270e18fc5400cca62e87f#4 | B28: نظام المقيمين المعتمدين | C28: المادة الخامسة والثلاثون : | D28: 1 | E28: إضافة فقرة أو مادة | H28: وتكون لهم عند ممارسة أعمالهم -مجتمعين أو منفردين- صلاحيات وسلطات الضبط الجنائي | I28: - إضافة عبارة إلى عجز المادة تنص على الآتي: "وتكون لهم عند ممارسة أعمالهم -مجتمعين أو منفردين- صلاحيات وسلطات الضبط الجنائي". | J28: https://laws.boe.gov.sa/BoeLaws/Laws/LawDetails/cad66e4d-38d3-4baa-8049-a9a700f1e7a8/1 | K28: يحتاج قرار المالك | L28: الأداة غير مذكورة في الملاحظة؛ أدوات النظام المرشحة: مرسوم ملكي م/109 1441/08/22، قرار مجلس الوزراء 57 1442/01/20، قرار مجلس الوزراء 123 1443/02/21، مرسوم ملكي م/190 1444/11/22 | O28: https://laws.boe.gov.sa/BoeLaws/Laws/Viewer/ea6a7b0c-de4b-4b29-b7b2-b02600af0044?attachmentTitle=المادة الخامسة والثلاثون : | S28: قاعدة: (^|\s|-)(يضاف|تضاف|اضافه|اضيفت|اضيف)\s | T28: add
A29: boe26-903826502452b9ffee66bf16#2 | B29: نظام الهيئة العامة للغذاء والدواء | C29: المادة السادسة: | D29: 1 | E29: إضافة فقرة أو مادة | F29: قرار مجلس الوزراء رقم (693) | G29: 1441/11/02 | I29: - إضافة ممثل من وزارة الصناعة والثروة المعدنية إلى عضوية مجلس إدارة الهيئة وذلك بموجب قرار مجلس الوزراء رقم (693) وتاريخ 1441/11/2هـ. | J29: https://laws.boe.gov.sa/BoeLaws/Laws/LawDetails/dd7a7d7d-a92d-431b-9ec3-a9a700f28a46/1 | K29: يحتاج قرار المالك | L29: النص الجديد غير مذكور في الملاحظة؛ عنوان المادة في صورة المرفق (ص 6، السياق: نص نظام أو سياق غير صريح)، والمقتطف الآلي مسودة تُطابق بالصورة ثم يُنقل النص حرفيًا | O29: https://laws.boe.gov.sa/BoeLaws/Laws/Viewer/f30c054b-a2a0-4379-a651-abef00a68fc6?attachmentTitle=المادة السادسة: | P29: 6 | Q29: https://laws.boe.gov.sa/BoeLaws/Laws/GetViewerImage/?imageFileName=f30c054b-a2a0-4379-a651-abef00a68fc6_Page_006.jpg | R29: والصناعة والثروة المعدنية)» الواردة في المادة (السادسة) من النظام. 7- إضافة ممثل من وزارة الصناعة والثروة المعدنية إلى عضوية مجلس إدارة الهيئة» المنصوص على تشكيله في المادة (السادسة) من النظام. ثالث عشر: ‎١‏ - تعديل نظام مدينة الملك عبدالله للطاقة الذرية والمتجددة الصادر بالامر الملكي رقم 26/9 وتاريخ */471/9١هء‏ وذلك بإضافة ممشل من وزارة الصناعة والثروة المعدنية إلى عضوية مجلس إدارة الهيئة» المنصوص على تشكيله في المادة (السادسة) من النظام. 1- تعديل قرار مجلس الوزراء رقم ‎)١١7(‏ وتتاريخ ‎4574/1/١5‏ اه»ء ونقاً للآتي: أ إحلال عبارة (وزير الطاقة رئيسا) محل عبارة (وزير الطاقة والصناعة والثروة المعدنية رثيساً) الواردة في الفقرة ‎)١(‏ من البند | (ولاً) من القراد. ب- إحلال عبارة (وزارة الطاقة) محل عبارة (وزارة الطاقة والصناعة والثروة 0 المعدنية) الواردة في الفقرة (©) من البند (أولأ» من القرار. | S29: قاعدة: (^|\s|-)(يضاف|تضاف|اضافه|اضيفت|اضيف)\s | T29: add
A30: boe26-0ace0d3a072544a1a1168927 | B30: نظام الوكالات التجارية | C30: المادة (6): | D30: 1 | E30: إضافة فقرة أو مادة | F30: مرسوم ملكي رقم (11) | I30: يضاف النص التالي إلى نظام (الوكالات التجارية) الصادر بالمرسوم الملكي رقم (11) لعام 1382. ونظام (المعايرة والمقاييس) الصادر بالمرسوم الملكي رقم (29) لعام 1383هـ ، بموجب المرسوم الملكي رقم م / 5 وتاريخ 11 / 6 / 1389 هـ . 1 – تشكل هيئة في وزارة التجارة والصناعة بقرار من وزيرها من ثلاثة أعضاء لتطبيق العقوبات الواردة في نظام الوكالات التجارية ونظام المعايرة والمقاييس. 2 – يجوز التظلم من قرارات هذه الهيئة أمام وزير التجارة والصناعة في خلال خمسة عشر يومًا من إبلاغها للمتظلم أو من ينوب عنه، وإلا أصبحت قراراتها نهائية بمضي المدة المذكورة وتصديق وزير التجارة والصناعة عليها. | J30: https://laws.boe.gov.sa/BoeLaws/Laws/LawDetails/b19a8aa6-7b50-43f0-ab8c-a9a700f1a446/1 | K30: يحتاج قرار المالك | L30: النص الجديد غير مذكور في الملاحظة؛ موضع مرشح للأداة في صورة المرفق (ص 2)، ويُنقل النص حرفيًا بعد المطابقة بالصورة | O30: https://laws.boe.gov.sa/BoeLaws/Laws/Viewer/144bd99c-09b4-410a-af22-9ec1290704f8?attachmentTitle=المادة (6): | P30: 2 | Q30: https://laws.boe.gov.sa/BoeLaws/Laws/GetViewerImage/?imageFileName=d90da66e-79ee-4633-9672-35844ef5fd77_Page_002.jpg | R30: ى » نص في نظامي الوكالا تالتجارية الصادرة بالمرسوم اللكي رقم ‎11‏ لعام 1205 والمعايرة والمقاي الصادر بالمرسو م الملكي رقم 11 لعام ير 1 على عقويات معينة تطبق على سغالف الاحكام الواردة ة النظامين آنفاالذكر ولم يشر فيبما الى الجهة التى لبا صلاحية تطبيق لك العقويات واشارت و التجارة والصناعة في خطاب مهعالي الوزير رقم 0)/م‏ ني ه1/1781/1[‏ الى الص | S30: قاعدة: (^|\s|-)(يضاف|تضاف|اضافه|اضيفت|اضيف)\s | T30: unclassified
A31: boe26-9ff16306400eb909018c3f4a#1 | B31: نظام توزيع الغاز الجاف وغاز البترول السائل للأغراض السكنية والتجارية | C31: المادة الثامنة عشرة: | D31: 1 | E31: قرار صادر بشأن المادة | F31: مرسوم ملكي رقم (م/112) | G31: 1443/11/09 | I31: - صدر المرسوم الملكي رقم (م/112) وتاريخ 1443/11/9هـ، وتضمن مايلي: | J31: https://laws.boe.gov.sa/BoeLaws/Laws/LawDetails/e4436403-31ee-439c-bac4-a9a700f2a17d/1 | K31: يحتاج قرار المالك | L31: الملاحظة تذكر قرارًا صادرًا بشأن المادة ولا تذكر أثره | O31: https://laws.boe.gov.sa/BoeLaws/Laws/Viewer/aedd995d-574d-46e3-863d-aee500e31402?attachmentTitle=المادة الثامنة عشرة: | S31: قاعدة: «صدر بشأن» | T31: substitute_phrase
A32: boe26-8c359b56cb3a8240ac6e54e8#1 | B32: نظام توزيع الغاز الجاف وغاز البترول السائل للأغراض السكنية والتجارية | C32: المادة العشرون: | D32: 1 | E32: قرار صادر بشأن المادة | F32: مرسوم ملكي رقم (م/112) | G32: 1443/11/09 | I32: - صدر المرسوم الملكي رقم (م/112) وتاريخ 1443/11/9هـ، والمتضمن مايلي: | J32: https://laws.boe.gov.sa/BoeLaws/Laws/LawDetails/e4436403-31ee-439c-bac4-a9a700f2a17d/1 | K32: يحتاج قرار المالك | L32: الملاحظة تذكر قرارًا صادرًا بشأن المادة ولا تذكر أثره | O32: https://laws.boe.gov.sa/BoeLaws/Laws/Viewer/d70d4105-ea4c-4d77-9ab5-aee500e2cc43?attachmentTitle=المادة العشرون: | S32: قاعدة: «صدر بشأن» | T32: substitute_phrase
A33: boe26-6e45640897717169e4b0dbb7#1 | B33: نظام ضريبة الدخل | C33: المادة السادسة والستون : الاعتراض والاستئناف | D33: 1 | E33: نص مادة معروض بلا صيغة تعديل | I33: •المادة السادسة والستين | J33: https://laws.boe.gov.sa/BoeLaws/Laws/LawDetails/23576008-1ce4-4685-ac3e-a9a700f2cb02/1 | K33: يحتاج قرار المالك | L33: الملاحظة نص مادة بلا أداة ولا فعل تعديل | O33: https://laws.boe.gov.sa/BoeLaws/Laws/Viewer/a10f96a0-6787-42cf-9a0a-1cd5d41db944?attachmentTitle=المادة السادسة والستون : الاعتراض والاستئناف | S33: لا فعل تعديل في الملاحظة | T33: amend_paragraph
A34: boe26-2be0ba3919b6ed696a77c746#1 | B34: نظام مهنة المحاسبة والمراجعة | C34: المادة الأولى | D34: 1 | E34: غير مصنف | F34: مرسوم ملكي رقم (م/169) | G34: 1446/08/10 | I34: - صدر المرسوم الملكي رقم (م/169) وتاريخ 1446/8/10هـ، وذلك على النحو الآتي: - حذف تعريف "الوزارة". | J34: https://laws.boe.gov.sa/BoeLaws/Laws/LawDetails/6435e205-a7ae-4a8c-9580-ad0000b6bef2/1 | K34: يحتاج قرار المالك | L34: الأثر غير صريح في الملاحظة | O34: https://laws.boe.gov.sa/BoeLaws/Laws/Viewer/03e73f9f-4ece-4af4-9a5f-b2db0090956a?attachmentTitle=المادة الأولى | S34: لا قاعدة | T34: delete
A35: boe26-d085a53f0b834df9531484e5 | B35: تنظيم الهيئة السعودية للمحامين | C35: المادة الثامنة: اختصاصات الجمعية العمومية | D35: 1 | E35: إعادة ترقيم + إلغاء فقرة | F35: قرار مجلس الوزراء رقم (143) | G35: 1447/02/18 | H35: "الموافقة على الحسابات الختامية للهيئة". وذلك بموجب قرار مجلس الوزراء رقم (143) وتاريخ 1447/2/18هـ. | I35: - حذف الفقرة (6) من هذه المادة وإعادة ترتيب فقرات المادة تبعاً لذلك، وذلك بموجب قرار مجلس الوزراء رقم (143) وتاريخ 1447/2/18هـ. - حذف صدر الفقرة (7) لتكون الفقرة بالنص الآتي: "الموافقة على الحسابات الختامية للهيئة". وذلك بموجب قرار مجلس الوزراء رقم (143) وتاريخ 1447/2/18هـ. | J35: https://laws.boe.gov.sa/BoeLaws/Laws/LawDetails/197be463-0b2b-4b67-9cd2-a9a700f2733b/1 | K35: مرجّح | O35: https://laws.boe.gov.sa/BoeLaws/Laws/Viewer/4eadec10-df33-4ef3-8d72-b35300ab8bea?attachmentTitle=المادة الثامنة: اختصاصات الجمعية العمومية | S35: قاعدة: عدة آثار في ملاحظة واحدة | T35: delete
A36: boe26-6f04f34a3cc1ed89e0ca0cf5 | B36: تنظيم الهيئة العامة للصناعات العسكرية | C36: المادة الرابعة: | D36: 1 | E36: إحلال عبارة + إضافة فقرة أو مادة + تعديل فقرة | F36: قرار مجلس الوزراء رقم (179) | G36: 1441/03/01 | H36: "5- نائب وزير الدفاع"، وإعادة ترتيب الفقرات الفرعية للفقرة (أ) تبعاً لذلك، وذلك بموجب قرار مجلس الوزراء رقم (179) وتاريخ 1 / 3 / 1441هـ. - عُدلت الفقرتين (ب) و(ج) وذلك بموجب قرار مجلس الوزراء رقم (179) وتاريخ 1 / 3 / 1441هـ. لتكونا بالنصين الآتيين: "ب- يجب ألا يقل مرتبة ممثلي الأجهزة الحكومية المشار إليهم في الفقرات (6) و(7) و(8) و(9) عن المرتبة (الممتازة) أو ا يعادلها". "ج- يختار رئيس المجلس نائباً له من الأعضاء المنصوص عليهم في الفقرات (1) و(2) و(3) و(4) و(5) من هذه المادة". | I36: • المادة الرابعة - عٌدلت الفقرة الفرعية (1) من الفقرة (أ) وذلك بإحلال عبارة "وزير الصناعة والثروة المعدنية" محل عبارة "وزير الطاقة والصناعة والثروة المعدنية"، وذلك بموجب قرار مجلس الوزراء رقم (179) وتاريخ 1 / 3 / 1441هـ. - أُضيفت فقرة فرعية تحمل الترتيب (5) إلى الفقرة (أ) بالنص الآتي: "5- نائب وزير الدفاع"، وإعادة ترتيب الفقرات الفرعية للفقرة (أ) تبعاً لذلك، وذلك بموجب قرار مجلس الوزراء رقم (179) وتاريخ 1 / 3 / 1441هـ. - عُدلت الفقرتين (ب) و(ج) وذلك بموجب قرار مجلس الوزراء رقم (179) وتاريخ 1 / 3 / 1441هـ. لتكونا بالنصين الآتيين: "ب- يجب ألا يقل مرتبة ممثلي الأجهزة الحكومية المشار إليهم في الفقرات (6) و(7) و(8) و(9) عن المرتبة (الممتازة) أو ا يعادلها". "ج- يختار رئيس المجلس نائباً له من الأعضاء المنصوص عليهم في الفقرات (1) و(2) و(3) و(4) و(5) من هذه المادة". | J36: https://laws.boe.gov.sa/BoeLaws/Laws/LawDetails/2f06117c-62e3-406c-a61e-a9fc009c5879/1 | K36: مرجّح | O36: https://laws.boe.gov.sa/BoeLaws/Laws/Viewer/b8207f93-969b-40cb-adb5-ab0c00bb0de3?attachmentTitle=المادة الرابعة: | S36: قاعدة: عدة آثار في ملاحظة واحدة | T36: amend_paragraph
A37: boe26-0c9c4a10bd334469cc40c5db | B37: تنظيم الهيئة العامة للمنشآت الصغيرة والمتوسطة | C37: المادة الثالثة: | D37: 1 | E37: إلغاء فقرة + إضافة فقرة أو مادة | F37: قرار مجلس الوزراء رقم (255) | G37: 1444/04/07 | I37: - حذف الفقرة (17) من هذه المادة وذلك بموجب قرار مجلس الوزراء رقم (255) وتاريخ 1444/4/7هـ، التي أُضيفت وصدر بشأنها قرار مجلس الوزراء رقم (225) وتاريخ 1441/3/22هـ. | J37: https://laws.boe.gov.sa/BoeLaws/Laws/LawDetails/e5bfc2bb-5ad0-493f-b10c-a9a700f1f2e1/1 | K37: مرجّح | O37: https://laws.boe.gov.sa/BoeLaws/Laws/Viewer/1a1fc72c-0319-4696-b2f9-ab1d00a4809f?attachmentTitle=المادة الثالثة: | S37: قاعدة: عدة آثار في ملاحظة واحدة | T37: delete
A38: boe26-638a9b166fe183e35243bcc7 | B38: نظام الإقامة المميزة | C38: المادة العاشرة | D38: 1 | E38: إلغاء فقرة + تعديل فقرة | F38: مرسوم ملكي رقم (م/84) | G38: 1445/06/11 | H38: فيما عدا ما نصّ عليه النظام واللائحة من حقوق ومزايا لحامل الإقامة المميزة وأسرته، تسري عليه وأسرته جميع الأنظمة واللوائح والتعليمات التي تسري على المقيم غير السعودي | I38: - صدر المرسوم الملكي رقم (م/84) وتاريخ 1445/6/11هـ، والذي نص على الآتي: - إلغاء الفقرة (1) التي نصت على الآتي: "تكون الحقوق والمزايا الممنوحة لحامل الإقامة المميزة وفقاً للنظام على سبيل الحصر". - تعديل الفقرة (3) لتصبح بالنص الآتي: "فيما عدا ما نصّ عليه النظام واللائحة من حقوق ومزايا لحامل الإقامة المميزة وأسرته، تسري عليه وأسرته جميع الأنظمة واللوائح والتعليمات التي تسري على المقيم غير السعودي". | J38: https://laws.boe.gov.sa/BoeLaws/Laws/LawDetails/5e9762df-2b15-4e66-8cdc-aa5200f62042/1 | K38: مرجّح | O38: https://laws.boe.gov.sa/BoeLaws/Laws/Viewer/c8ae6208-d3fa-4226-bd0b-b0f800c40c60?attachmentTitle=المادة العاشرة | S38: قاعدة: عدة آثار في ملاحظة واحدة | T38: repeal
A39: boe26-fc92d186b5c514d15b5f3a24#2 | B39: نظام البريد | C39: المادة الأولى | D39: 1 | E39: حذف عبارة | F39: قرار مجلس الوزراء رقم (705) | G39: 1443/12/27 | I39: - حذف عبارة "وذلك بالاتفاق مع الهيئة العامة للنقل فيما يتصل باختصاصاتها المقررة نظاماً، وبما لا يخالف أحكام النظام" من الفقرة (8) من تعريف (الخدمات البريدية). | J39: https://laws.boe.gov.sa/BoeLaws/Laws/LawDetails/8ca91427-5be7-4807-80ae-adc700a97f0d/1 | K39: مرجّح | L39: الأداة غير مذكورة في الملاحظة؛ استُنتجت لأنها الأداة الوحيدة في ملاحظات النظام نفسه | O39: https://laws.boe.gov.sa/BoeLaws/Laws/Viewer/90fef0b3-713c-45f2-9a80-aef500eb0817?attachmentTitle=المادة الأولى | S39: قاعدة: (الغاء|حذف|حذفت)\s+(ال)?(عباره|كلمه) | T39: delete
A40: boe26-fc92d186b5c514d15b5f3a24#3 | B40: نظام البريد | C40: المادة الأولى | D40: 1 | E40: حذف عبارة | F40: قرار مجلس الوزراء رقم (705) | G40: 1443/12/27 | I40: - حذف عبارة "بالاتفاق مع الهيئة العامة للنقل" الواردة في تعريف (الطرود). | J40: https://laws.boe.gov.sa/BoeLaws/Laws/LawDetails/8ca91427-5be7-4807-80ae-adc700a97f0d/1 | K40: مرجّح | L40: الأداة غير مذكورة في الملاحظة؛ استُنتجت لأنها الأداة الوحيدة في ملاحظات النظام نفسه | O40: https://laws.boe.gov.sa/BoeLaws/Laws/Viewer/90fef0b3-713c-45f2-9a80-aef500eb0817?attachmentTitle=المادة الأولى | S40: قاعدة: (الغاء|حذف|حذفت)\s+(ال)?(عباره|كلمه) | T40: delete
...

Sheet الفئة 2 - بلا أداة
A1: معرّف الملاحظة | B1: النظام | C1: المادة | D1: الفئة | E1: الأثر المقترح | F1: الأداة | G1: تاريخها | H1: النص الجديد (حرفي) | I1: الدليل (اقتباس) | J1: المصدر | K1: الثقة | L1: سبب عدم الحسم | M1: قرار المالك | N1: ملاحظته | O1: رابط مرفق الأداة | P1: صفحة المسودة | Q1: صورة الصفحة | R1: مسودة آلية من الصورة (للمطابقة فقط) | S1: أساس التصنيف | T1: تصنيف المحلل الآلي
A2: boe26-a62387e14e80f7eed4efd224 | B2: تنظيم الهيئة السعودية للمدن الصناعية ومناطق التقنية | C2: المادة الأولى: | D2: 2 | E2: تعديل تعريف | H2: وزير الطاقة والصناعة والثروة المعدنية | I2: تعريف ( الوزير ) الوارد في المادة الأولى تعديل التعريف ليكون "وزير الطاقة والصناعة والثروة المعدنية" | J2: https://laws.boe.gov.sa/BoeLaws/Laws/LawDetails/f9bd197e-980e-4e9f-948c-a9a700f2994e/1 | K2: يحتاج قرار المالك | L2: الأداة غير مذكورة في الملاحظة؛ أدوات النظام المرشحة: قرار مجلس الوزراء 136 1424/05/21، قرار مجلس الوزراء 403 1442/07/18، قرار مجلس الوزراء 17 1444/01/04 | O2: https://laws.boe.gov.sa/BoeLaws/Laws/Viewer/11755405-f429-459a-82b6-aa1d01153964?attachmentTitle=المادة الأولى: | S2: قاعدة: (تعديل|عدل|عدلت)\s+(هذا\s+)?(التعريف|تعريف) | T2: amend_definition
A3: boe26-459ab3d2a05e5796f7db005b | B3: تنظيم الهيئة العامة للإعلام المرئي والمسموع | C3: المادة الأولى: | D3: 2 | E3: تعديل تعريف | H3: الرئيس: الرئيس التنفيذي. | I3: تعريف ( الرئيس ) الوارد في المادة (الاولى) تعديل التعريف ليصبح بالنص الآتي: الرئيس: الرئيس التنفيذي. | J3: https://laws.boe.gov.sa/BoeLaws/Laws/LawDetails/13445632-e42b-4576-a671-a9a700f175f6/1 | K3: يحتاج قرار المالك | L3: الأداة غير مذكورة في الملاحظة؛ أدوات النظام المرشحة: قرار مجلس الوزراء 129 1435/04/03، قرار مجلس الوزراء 265 1439/05/27 | O3: https://laws.boe.gov.sa/BoeLaws/Laws/Viewer/3f2c59c9-6ee6-4b07-9a3c-aa1d011300fd?attachmentTitle=المادة الأولى: | S3: قاعدة: (تعديل|عدل|عدلت)\s+(هذا\s+)?(التعريف|تعريف) | T3: amend_definition
A4: boe26-93372df353878dc71582fd33 | B4: تنظيم الهيئة العامة للإعلام المرئي والمسموع | C4: المادة العاشرة: | D4: 2 | E4: تعديل مادة | H4: يكون للهيئة رئيس تنفيذي يُعين ويُعفى من منصبه بقرار من المجلس، ويحدد القرار أجره ومزاياه المالية | I4: عُدلت المادة لتصبح بالنص الآتي: "يكون للهيئة رئيس تنفيذي يُعين ويُعفى من منصبه بقرار من المجلس، ويحدد القرار أجره ومزاياه المالية". | J4: https://laws.boe.gov.sa/BoeLaws/Laws/LawDetails/13445632-e42b-4576-a671-a9a700f175f6/1 | K4: يحتاج قرار المالك | L4: الأداة غير مذكورة في الملاحظة؛ أدوات النظام المرشحة: قرار مجلس الوزراء 129 1435/04/03، قرار مجلس الوزراء 265 1439/05/27 | O4: https://laws.boe.gov.sa/BoeLaws/Laws/Viewer/5c945087-02f4-4970-b784-aa1d0113eb58?attachmentTitle=المادة العاشرة: | S4: قاعدة: (عدلت|عدل|تعديل|تعديلات|يعدل|ليعدل)\b.{0,40}(الماده|المواد)| | T4: amend_article
A5: boe26-52491bf8d9a64922ca2b2cfe | B5: تنظيم الهيئة العامة للاستثمار | C5: المادة التاسعة : | D5: 2 | E5: تعديل فقرة | H5: 1 - يؤسس بالهيئة مركز الخدمة الشاملة يحوي مكاتب اتصال تضم ممثلين متفرغين لجميع الدوائر الحكومية ذات العلاقة بالاستثمار كوزارات الداخلية ( المديرية العامة للجوازات ، الإدارة العامة لشؤون الاستقدام )، والخارجية والتجارة ، والصناعة والكهرباء ، والمالية والاقتصاد الوطني ( مصلحة الزكاة والدخل ، صندوق التنمية الصناعية السعودي )، والزراعة والمياه ، والعمل والشؤون الاجتماعية ( مكتب العمل والعمال )، والبترول والثروة المعدنية ، والعدل ، والشؤون البلدية والقروية ، وللمجلس تعديل الجهات المذكورة في هذا التنظيم بناء على اقتراح من مجلس الإدارة. | I5: عدلت الفقرة الأولى من المادة التاسعة بموجب قرار المجلس الاقتصادي الأعلى رقم (7/23) بتاريخ 23 / 3 / 1423 هـ ، لتصبح على النحو الآتى : 1 - يؤسس بالهيئة مركز الخدمة الشاملة يحوي مكاتب اتصال تضم ممثلين متفرغين لجميع الدوائر الحكومية ذات العلاقة بالاستثمار كوزارات الداخلية ( المديرية العامة للجوازات ، الإدارة العامة لشؤون الاستقدام )، والخارجية والتجارة ، والصناعة والكهرباء ، والمالية والاقتصاد الوطني ( مصلحة الزكاة والدخل ، صندوق التنمية الصناعية السعودي )، والزراعة والمياه ، والعمل والشؤون الاجتماعية ( مكتب العمل والعمال )، والبترول والثروة المعدنية ، والعدل ، والشؤون البلدية والقروية ، وللمجلس تعديل الجهات المذكورة في هذا التنظيم بناء على اقتراح من مجلس الإدارة. | J5: https://laws.boe.gov.sa/BoeLaws/Laws/LawDetails/c47e6347-4d53-4a50-b92d-a9a700f1a76d/1 | K5: يحتاج قرار المالك | L5: الأداة غير مذكورة في الملاحظة؛ أدوات النظام المرشحة: قرار مجلس الوزراء 124 1427/05/16، قرار مجلس الوزراء 264 1440/05/16 | O5: https://laws.boe.gov.sa/BoeLaws/Laws/Viewer/373b66af-b14c-41c1-8470-f366263fc5fa?attachmentTitle=المادة التاسعة : | S5: قاعدة: (عدلت|عدل|تعديل|تعديلات)\s+(صدر\s+|اخر\s+لهذه\s+)?(هذه\s+)?( | T5: amend_paragraph
A6: boe26-cb55b762d8643877abf33e10 | B6: تنظيم الهيئة العامة للاستثمار | C6: المادة الرابعة : | D6: 2 | E6: نص مادة معروض بلا صيغة تعديل | H6: المحافظ رئيساً ممثل من وزارة الداخلية عضواً ممثل من وزارة الخارجية عضواً ممثل من وزارة التجارة عضواً ممثل من وزارة الزارعة والمياة عضواً ممثل من وزارة البترول والثروة المعدنية عضوا ممثل من وزارة الصناعة والكهرباء عضواً ممثل من وزارة المالية والاقتصاد الوطني عضواً ممثل من وزارة التخطيط عضوا ممثل من وزارة العمل والشؤون الاجتماعية عضوا ممثل من مؤسسة النقد العربي السعودي عضوا وعضوان من القطاع الخاص يعينان بقرار من الرئيس بناء على اقتراح من المحافظ. ويجب ألا تقل مرتبة ممثلي الأجهزة الحكومية في مجل الإدارة عن الرابعة عشر. وتكون مدة العضوية في مجلس الادرة ثلاث سنوات فقط. | I6: يشكل مجلس إدارة الهيئة على النحو التالي : المحافظ رئيساً ممثل من وزارة الداخلية عضواً ممثل من وزارة الخارجية عضواً ممثل من وزارة التجارة عضواً ممثل من وزارة الزارعة والمياة عضواً ممثل من وزارة البترول والثروة المعدنية عضوا ممثل من وزارة الصناعة والكهرباء عضواً ممثل من وزارة المالية والاقتصاد الوطني عضواً ممثل من وزارة التخطيط عضوا ممثل من وزارة العمل والشؤون الاجتماعية عضوا ممثل من مؤسسة النقد العربي السعودي عضوا وعضوان من القطاع الخاص يعينان بقرار من الرئيس بناء على اقتراح من المحافظ. ويجب ألا تقل مرتبة ممثلي الأجهزة الحكومية في مجل الإدارة عن الرابعة عشر. وتكون مدة العضوية في مجلس الادرة ثلاث سنوات فقط. | J6: https://laws.boe.gov.sa/BoeLaws/Laws/LawDetails/c47e6347-4d53-4a50-b92d-a9a700f1a76d/1 | K6: يحتاج قرار المالك | L6: الملاحظة نص مادة بلا أداة ولا فعل تعديل | O6: https://laws.boe.gov.sa/BoeLaws/Laws/Viewer/c1b1f3db-8836-417d-9f30-ff14b310a39a?attachmentTitle=المادة الرابعة : | S6: لا فعل تعديل في الملاحظة | T6: unclassified
A7: boe26-7065cae8f349897349811f6b | B7: تنظيم الهيئة العامة للاستثمار | C7: المادة السادسة : | D7: 2 | E7: إحلال عبارة | H7: يجتمع مجلس الإدارة بدعوة من الرئيس مرة كل شهر على الأقل، وعلى الرئيس دعوة مجلس الإدارة إذا طلب ذلك نصف الأعضاء على الأقل، ويجب أن تشمل الدعوة على جدول الأعمال، ويشترط لصحة الاجتماع حضور أغلبية الأعضاء على الأقل بمن فيهم الرئيس أو من ينيبه من الأعضاء،... | I7: •المادة السادسة -إحلال كلمة "الرئيس" محل كلمة "المحافظ" وعبارة "رئيس مجلس الإدارة" أينما وردتا في هذه المادة، لتكون المادة بعد التعديل بالنص الآتي: "يجتمع مجلس الإدارة بدعوة من الرئيس مرة كل شهر على الأقل، وعلى الرئيس دعوة مجلس الإدارة إذا طلب ذلك نصف الأعضاء على الأقل، ويجب أن تشمل الدعوة على جدول الأعمال، ويشترط لصحة الاجتماع حضور أغلبية الأعضاء على الأقل بمن فيهم الرئيس أو من ينيبه من الأعضاء،...". | J7: https://laws.boe.gov.sa/BoeLaws/Laws/LawDetails/c47e6347-4d53-4a50-b92d-a9a700f1a76d/1 | K7: يحتاج قرار المالك | L7: الأداة غير مذكورة في الملاحظة؛ أدوات النظام المرشحة: قرار مجلس الوزراء 124 1427/05/16، قرار مجلس الوزراء 264 1440/05/16 | O7: https://laws.boe.gov.sa/BoeLaws/Laws/Viewer/81e4d56d-e947-45a3-844f-aa7600932523?attachmentTitle= المادة السادسة : | S7: قاعدة: (تعديل|عدل|عدلت)\s+(اسم|مسمي|عباره|العباره)|حل\s+اسم|احلال|ا | T7: substitute_phrase
A8: boe26-47cd9043ec40936183a794dd | B8: تنظيم الهيئة العامة للاستثمار | C8: المادة العاشرة : | D8: 2 | E8: إضافة فقرة أو مادة | H8: العاشرة | I8: الفقرة (2) من المادة (العاشرة) إضافة عبارة "وفقاً لما تحدده اللائحة" إلى نهاية هذه الفقرة. | J8: https://laws.boe.gov.sa/BoeLaws/Laws/LawDetails/c47e6347-4d53-4a50-b92d-a9a700f1a76d/1 | K8: يحتاج قرار المالك | L8: الأداة غير مذكورة في الملاحظة؛ أدوات النظام المرشحة: قرار مجلس الوزراء 124 1427/05/16، قرار مجلس الوزراء 264 1440/05/16 | O8: https://laws.boe.gov.sa/BoeLaws/Laws/Viewer/6c0e2e48-26a3-4ad1-aa37-aa3a01020041?attachmentTitle=المادة العاشرة : | S8: قاعدة: (^|\s|-)(يضاف|تضاف|اضافه|اضيفت|اضيف)\s | T8: add
A9: boe26-24eabc0311e31a32e65619e7 | B9: تنظيم صندوق الشهداء والمصابين والأسرى والمفقودين | C9: المادة الأولى : التعريفات : | D9: 2 | E9: تعديل تعريف | H9: الوزير: وزير الدفاع | I9: تعريف الوزير من المادة (الأولى) * عُدل التعريف ليكون بالنص الآتي: "الوزير: وزير الدفاع". | J9: https://laws.boe.gov.sa/BoeLaws/Laws/LawDetails/62d14b10-5bee-46e9-870a-a9a700f19762/1 | K9: يحتاج قرار المالك | L9: الأداة غير مذكورة في الملاحظة؛ أدوات النظام المرشحة: قرار مجلس الوزراء 707 1440/12/26، قرار مجلس الوزراء 195 1444/03/15، قرار مجلس الوزراء 119 1446/02/02 | O9: https://laws.boe.gov.sa/BoeLaws/Laws/Viewer/66de474c-549c-4b8c-9116-aa1c01702900?attachmentTitle=المادة الأولى : التعريفات : | S9: قاعدة: (تعديل|عدل|عدلت)\s+(هذا\s+)?(التعريف|تعريف) | T9: amend_definition
A10: boe26-fb16154fdc945bf70d54952f | B10: تنظيم صندوق الشهداء والمصابين والأسرى والمفقودين | C10: المادة الخامسة : | D10: 2 | E10: تعديل مادة | H10: يكون للصندوق مجلس أمناء برئاسة الوزير، وعضوية وزير الداخلية، ووزير الحرس الوطني، ووزير الشؤون الإسلامية والدعوة والإرشاد، ووزير المالية، ووزير العمل والتنمية الاجتماعية، ويعين الرئيس بقرار منه أربعة أعضاء آخرين -على الأقل- من المشهود لهم بالإسهام في المجال الخيري | I10: * عُدلت المادة لتكون بالنص الآتي: "يكون للصندوق مجلس أمناء برئاسة الوزير، وعضوية وزير الداخلية، ووزير الحرس الوطني، ووزير الشؤون الإسلامية والدعوة والإرشاد، ووزير المالية، ووزير العمل والتنمية الاجتماعية، ويعين الرئيس بقرار منه أربعة أعضاء آخرين -على الأقل- من المشهود لهم بالإسهام في المجال الخيري". | J10: https://laws.boe.gov.sa/BoeLaws/Laws/LawDetails/62d14b10-5bee-46e9-870a-a9a700f19762/1 | K10: يحتاج قرار المالك | L10: الأداة غير مذكورة في الملاحظة؛ أدوات النظام المرشحة: قرار مجلس الوزراء 707 1440/12/26، قرار مجلس الوزراء 195 1444/03/15، قرار مجلس الوزراء 119 1446/02/02 | O10: https://laws.boe.gov.sa/BoeLaws/Laws/Viewer/63dda844-ae3b-4560-884c-aa1c0170b1f8?attachmentTitle=المادة الخامسة : | S10: قاعدة: (عدلت|عدل|تعديل|تعديلات|يعدل|ليعدل)\b.{0,40}(الماده|المواد)| | T10: amend_article
A11: boe26-ed33012bf1bf690998825e75 | B11: تنظيم صندوق مدينة الملك فهد الطبية | C11: المادة العاشرة : | D11: 2 | E11: تعديل مادة | H11: تكون إيرادات الصندوق على النحو التالي: 1- إيرادات التعليم والتدريب المستمر. 2- إيرادات النشاط الاجتماعي. 3- إيرادات الاستشارات المتخصصة. 4- إيرادات تقديم الخدمات المساندة. 5- أي تبرع أو هبة يتلقاها الصندوق. 6- المبالغ المحصلة نتيجة مخالفات أنظمة ولوائح المدينة. 7- فوائض أموال الصندوق المدورة من السنة السابقة. 8- الإيرادات الناتجة من استغلال براءات الاختراع وحقوق الملكية الفكرية وفق أسس استثمارية. 9- الإيرادات الناتجة من تأسيس حاضنات التقنية الصحية والاستثمار فيها. 10- الإيرادات الناتجة من مشاركة القطاع العام أو الخاص في إقامة برامج وإجراء الأبحاث في المجالات الطبية والطبية المساعدة والتقنيات الطبية واستثمار ما تسفر عنه من نتائج علمية. 11- الإيرادات الناتجة من إقامة برامج تدار وفق أسس استثمارية آمنة تمول من فوائض أموال الصندوق المدورة بما لا يؤثر على تحقيق أهدافه. 12- الإيرادات الناتجة من استثمار المواقع القابلة للاستثمار داخل حرم المدينة بالاتفاق المباشر مع مستثمرين. 13- الإيرادات الناتجة من استثمار إيرادات الصندوق المدورة في الأوعية الاستثمارية الآمنة. 14- الإيرادات الناتجة من إنشاء الشركات والمشاركة فيها في المجالات الطبية والطبية المساعدة والتقنيات الطبية والتعليم والتدريب الصحي | I11: عُدلت المادة (العاشرة) لتكون بالنص الآتي: "تكون إيرادات الصندوق على النحو التالي: 1- إيرادات التعليم والتدريب المستمر. 2- إيرادات النشاط الاجتماعي. 3- إيرادات الاستشارات المتخصصة. 4- إيرادات تقديم الخدمات المساندة. 5- أي تبرع أو هبة يتلقاها الصندوق. 6- المبالغ المحصلة نتيجة مخالفات أنظمة ولوائح المدينة. 7- فوائض أموال الصندوق المدورة من السنة السابقة. 8- الإيرادات الناتجة من استغلال براءات الاختراع وحقوق الملكية الفكرية وفق أسس استثمارية. 9- الإيرادات الناتجة من تأسيس حاضنات التقنية الصحية والاستثمار فيها. 10- الإيرادات الناتجة من مشاركة القطاع العام أو الخاص في إقامة برامج وإجراء الأبحاث في المجالات الطبية والطبية المساعدة والتقنيات الطبية واستثمار ما تسفر عنه من نتائج علمية. 11- الإيرادات الناتجة من إقامة برامج تدار وفق أسس استثمارية آمنة تمول من فوائض أموال الصندوق المدورة بما لا يؤثر على تحقيق أهدافه. 12- الإيرادات الناتجة من استثمار المواقع القابلة للاستثمار داخل حرم المدينة بالاتفاق المباشر مع مستثمرين. 13- الإيرادات الناتجة من استثمار إيرادات الصندوق المدورة في الأوعية الاستثمارية الآمنة. 14- الإيرادات الناتجة من إنشاء الشركات والمشاركة فيها في المجالات الطبية والطبية المساعدة والتقنيات الطبية والتعليم والتدريب الصحي". | J11: https://laws.boe.gov.sa/BoeLaws/Laws/LawDetails/5f028fb6-ec65-4745-8836-a9a700f28c38/1 | K11: يحتاج قرار المالك | L11: الأداة غير مذكورة في الملاحظة، ولا أداة في ملاحظات النظام | O11: https://laws.boe.gov.sa/BoeLaws/Laws/Viewer/e92c385d-9829-4f5e-b0fd-aa1c016f2a56?attachmentTitle=المادة العاشرة : | S11: قاعدة: (عدلت|عدل|تعديل|تعديلات|يعدل|ليعدل)\b.{0,40}(الماده|المواد)| | T11: amend_article
A12: boe26-96b66236f688eccb0f880661 | B12: تنظيم هيئة الاتصالات والفضاء والتقنية | C12: المادة الرابعة: | D12: 2 | E12: تعديل فقرة | H12: يكون للهيئة مجلس إداة برئاسة الوزير، وعضوية كل من: أ- محافظ الهيئة ويكون نائباً لرئيس المجلس. ب- ممثل من وزارة الاتصالات وتقنية المعلومات. ج- ممثل من وزارة المالية. د- ممثل من وزارة التجارة والاستثمار. هـ- ممثل من مدينة الملك عبدالعزيز للعلوم والتقنية. و- ممثل من رئاسة أمن الدولة. ز- ثلاثة أعضاء من القطاع الخاص يتم ترشيحهم من قبل الوزير ويصدر بتعيينهم قرار من مجلس الوزراء. | I12: - عُدلت الفقرة (1) من هذه المادة وذلك بموجب قرار مجلس الوزراء رقم () وتاريخ 1440/2/21هـ، لتكون بلنص الآتي: يكون للهيئة مجلس إداة برئاسة الوزير، وعضوية كل من: أ- محافظ الهيئة ويكون نائباً لرئيس المجلس. ب- ممثل من وزارة الاتصالات وتقنية المعلومات. ج- ممثل من وزارة المالية. د- ممثل من وزارة التجارة والاستثمار. هـ- ممثل من مدينة الملك عبدالعزيز للعلوم والتقنية. و- ممثل من رئاسة أمن الدولة. ز- ثلاثة أعضاء من القطاع الخاص يتم ترشيحهم من قبل الوزير ويصدر بتعيينهم قرار من مجلس الوزراء. | J12: https://laws.boe.gov.sa/BoeLaws/Laws/LawDetails/f327464b-2f5a-475d-aa94-a9a700f2e817/1 | K12: يحتاج قرار المالك | L12: الأداة غير مذكورة في الملاحظة؛ أدوات النظام المرشحة: قرار مجلس الوزراء 133 1424/05/21، قرار مجلس الوزراء 430 1446/06/23 | O12: https://laws.boe.gov.sa/BoeLaws/Laws/Viewer/064ffdcf-b271-4aff-9429-b3f500db83bd?attachmentTitle=المادة الرابعة: | S12: قاعدة: (عدلت|عدل|تعديل|تعديلات)\s+(صدر\s+|اخر\s+لهذه\s+)?(هذه\s+)?( | T12: amend_paragraph
A13: boe26-bf508ef459f02c3c0b8643f6 | B13: تنظيم هيئة النقل العام ( الهيئة العامة للنقل ) | C13: المادة الخامسة: | D13: 2 | E13: تعديل فقرة | H13: "يكون للهيئة مجلس إدارة يعين رئيسه بأمر ملكي، وتكون العضوية فيه على النحو الآتي:...". إحلال عبارة "رئيس المجلس" محل كلمة "الوزير" الواردة في الفقرة الفرعية (ح) من الفقرة (1) من هذه المادة. | I13: - عُدلت صدر الفقرة (1) من المادة (الخامسة) ليكون بالنص الآتي: "يكون للهيئة مجلس إدارة يعين رئيسه بأمر ملكي، وتكون العضوية فيه على النحو الآتي:...". إحلال عبارة "رئيس المجلس" محل كلمة "الوزير" الواردة في الفقرة الفرعية (ح) من الفقرة (1) من هذه المادة. | J13: https://laws.boe.gov.sa/BoeLaws/Laws/LawDetails/9a1c4977-c539-4e01-8c88-a9a700f2efa9/1 | K13: يحتاج قرار المالك | L13: الأداة غير مذكورة في الملاحظة؛ أدوات النظام المرشحة: قرار مجلس الوزراء 707 1438/11/30، قرار مجلس الوزراء 631 1440/11/06، قرار مجلس الوزراء 586 1444/08/22، قرار مجلس الوزراء 382 1446/05/17 | O13: https://laws.boe.gov.sa/BoeLaws/Laws/Viewer/2d566e4c-ed18-4cad-8436-afd200cfa867?attachmentTitle=المادة الخامسة: | S13: قاعدة: (عدلت|عدل|تعديل|تعديلات)\s+(صدر\s+|اخر\s+لهذه\s+)?(هذه\s+)?( | T13: substitute_phrase
A14: boe26-4e70ea1d6e40fab7cd860549 | B14: تنظيم هيئة الهلال الأحمر السعودي | C14: المادة الخامسة : | D14: 2 | E14: غير مصنف | I14: مع عدم الإخلال باختصاصات الجهات الأخرى ، تتولى الهيئة في سبيل تحقيق أهدافها المهمات الآتية : 1 - الاستعداد والعمل في زمن السلم والحرب بصفتها مساعدة للإدارات الطبية في القطاعات العسكرية على سبيل التعاون والتكامل لمصلحة جميع ضحايا الحروب المدنيين والعسكريين في جميع الأحوال المنصوص عليها في اتفاقيات جنيف الأربع لعام 1949م والبروتوكولين الإضافيين لها لعام 1977م، ويشمل ذلك على وجه خاص ما يلي : أ‌ - نقل الجرحى والمرضى ، وإنشاء وتشغيل مستشفيات الهلال الأحمر السعودي في المواقع التي تحددها القيادة العسكرية . ب - توفير وسائل نقل ومساعدة ضحايا الحرب . ج - التوسط في تبادل المراسلات الخاصة بأسرى وضحايا الحرب. د - العمل على توفير وتخزين وسائل ومعدات الإيواء والأدوية وجميع ما يلزم لعلاج المرضى والجرحى والعناية بالأسرى . 2 - تمثيل المملكة أمام الجهات الدولية المختصة بوصفها الجهة الوحيدة التي تمثل الهلال الأحمر في المملكة. 3 - تقديم الخدمات الإسعافية الطبية بوصفها المقدم الرئيس لهذه الخدمة في المملكة ، ويشمل ذلك النقل الإسعافي ، والخدمات الصحية لمرحلة ما قبل المستشفى للمرضى والمصابين في الحوادث والكوارث . | J14: https://laws.boe.gov.sa/BoeLaws/Laws/LawDetails/49ab78f2-a4ad-42f8-97ce-a9a700f28035/1 | K14: يحتاج قرار المالك | L14: الأثر غير صريح في الملاحظة | O14: https://laws.boe.gov.sa/BoeLaws/Laws/Viewer/99668380-e888-449c-8bd9-a9a700f28119?attachmentTitle=المادة الخامسة : | S14: لا قاعدة | T14: unclassified
A15: boe26-9ed17e89824dcb8874240fc1 | B15: نظام المشاركة بالوقت فى الوحدات العقارية السياحية | C15: المادة الأولى: التعريفات: | D15: 2 | E15: تعديل تعريف | H15: عقد، أو مجموعة عقود تبرم مقابل مبلغ مالي معين، لمدة محددة أو قابلة للتحديد من السنة -تتكرر لثلاث سنوات على الأقل- يتم بموجبها إنشاء حق انتفاع يتعلق باستعمال وحدة عقارية واحدة أو أكثر، أو التنازل عنه، أو أي حق آخر | I15: المادة الأولى ( تعريف عقد المشاركة بالوقت ) عُدل التعريف ليكون بالنص الآتي: "عقد، أو مجموعة عقود تبرم مقابل مبلغ مالي معين، لمدة محددة أو قابلة للتحديد من السنة -تتكرر لثلاث سنوات على الأقل- يتم بموجبها إنشاء حق انتفاع يتعلق باستعمال وحدة عقارية واحدة أو أكثر، أو التنازل عنه، أو أي حق آخر". | J15: https://laws.boe.gov.sa/BoeLaws/Laws/LawDetails/3ab82e3c-de46-4463-a939-a9a700f1b2af/1 | K15: يحتاج قرار المالك | L15: الأداة غير مذكورة في الملاحظة؛ أدوات النظام المرشحة: مرسوم ملكي م/75 1435/12/02، مرسوم ملكي م/17 1439/01/21، قرار مجلس الوزراء 96 1442/02/05 | O15: https://laws.boe.gov.sa/BoeLaws/Laws/Viewer/3876fd03-5776-4b05-8758-ac4500c5cf2b?attachmentTitle=المادة الأولى: التعريفات: | S15: قاعدة: (تعديل|عدل|عدلت)\s+(هذا\s+)?(التعريف|تعريف) | T15: amend_definition
A16: boe26-3f51ef3ce2c3d360a55f9a61 | B16: نظام المشاركة بالوقت فى الوحدات العقارية السياحية | C16: المادة الثانية: الترخيص بمزاولة النشاط : | D16: 2 | E16: تعديل فقرة | H16: 1- لا تجوز مزاولة نشاط المشاركة بالوقت أو التسويق له قبل الحصول على ترخيص من الهيئة، وذلك وفقاً للشروط التي تحددها اللائحة | I16: الفقرة ( 1 ) من المادة الثانية عُدلت الفقرة ليكون نصها: "1- لا تجوز مزاولة نشاط المشاركة بالوقت أو التسويق له قبل الحصول على ترخيص من الهيئة، وذلك وفقاً للشروط التي تحددها اللائحة". | J16: https://laws.boe.gov.sa/BoeLaws/Laws/LawDetails/3ab82e3c-de46-4463-a939-a9a700f1b2af/1 | K16: يحتاج قرار المالك | L16: الأداة غير مذكورة في الملاحظة؛ أدوات النظام المرشحة: مرسوم ملكي م/75 1435/12/02، مرسوم ملكي م/17 1439/01/21، قرار مجلس الوزراء 96 1442/02/05 | O16: https://laws.boe.gov.sa/BoeLaws/Laws/Viewer/e4ecf53b-4b6f-42eb-8211-aa1d010e784e?attachmentTitle=المادة الثانية: الترخيص بمزاولة النشاط : | S16: قاعدة: (عدلت|عدل|تعديل|تعديلات)\s+(صدر\s+|اخر\s+لهذه\s+)?(هذه\s+)?( | T16: amend_paragraph
